2022-02-07 21:26:09 INFO - User-f8f190a0-8683-11ec-8657-1e00310cd05
2022-02-07 21:26:09 ERROR - Document doesnt existkiran_attal@scmhrd.edu
2022-02-07 21:26:09 INFO - 127.0.0.1 - - [07/Feb/2022 21:26:09] "[33mPUT //user/User-f8f190a0-8683-11ec-8657-1e00310cd05 HTTP/1.1[0m" 404 -
2022-02-07 21:31:19 INFO -  * Running on http://127.0.0.1:5000/ (Press CTRL+C to quit)
2022-02-07 21:31:21 INFO - User-f8f190a0-8683-11ec-8657-1e00310cd05
2022-02-07 21:31:22 ERROR - Document doesnt existkiran_attal@scmhrd.edu
2022-02-07 21:31:22 INFO - 127.0.0.1 - - [07/Feb/2022 21:31:22] "[33mPUT //user/User-f8f190a0-8683-11ec-8657-1e00310cd05 HTTP/1.1[0m" 404 -
2022-02-07 21:38:00 INFO -  * Running on http://127.0.0.1:5000/ (Press CTRL+C to quit)
2022-02-07 21:38:02 INFO - User-f8f190a0-8683-11ec-8657-1e00310cd05
2022-02-07 21:38:03 ERROR - Document doesnt existkiran_attal@scmhrd.edu
2022-02-07 21:38:03 INFO - 127.0.0.1 - - [07/Feb/2022 21:38:03] "[31m[1mPUT //user/User-f8f190a0-8683-11ec-8657-1e00310cd05 HTTP/1.1[0m" 401 -
2022-02-07 21:38:22 INFO -  * Running on http://127.0.0.1:5000/ (Press CTRL+C to quit)
2022-02-07 21:38:24 INFO - User-f8f190a0-8683-11ec-8657-1e00310cd05
2022-02-07 21:38:25 ERROR - Document doesnt existkiran_attal@scmhrd.edu
2022-02-07 21:38:25 INFO - 127.0.0.1 - - [07/Feb/2022 21:38:25] "[33mPUT //user/User-f8f190a0-8683-11ec-8657-1e00310cd05 HTTP/1.1[0m" 404 -
2022-02-07 21:41:44 INFO -  * Running on http://127.0.0.1:5000/ (Press CTRL+C to quit)
2022-02-07 21:41:46 INFO - User-f8f190a0-8683-11ec-8657-1e00310cd05
2022-02-07 21:41:47 ERROR - Document doesnt existkiran_attal@scmhrd.edu
2022-02-07 21:41:47 INFO - 127.0.0.1 - - [07/Feb/2022 21:41:47] "[33mPUT //user/User-f8f190a0-8683-11ec-8657-1e00310cd05 HTTP/1.1[0m" 404 -
2022-02-07 21:44:43 INFO -  * Running on http://127.0.0.1:5000/ (Press CTRL+C to quit)
2022-02-07 21:44:45 INFO - User-f8f190a0-8683-11ec-8657-1e00310cd05
2022-02-07 21:44:46 ERROR - Document doesnt existkiran_attal@scmhrd.edu
2022-02-07 21:44:46 ERROR - Exception on /user/User-f8f190a0-8683-11ec-8657-1e00310cd05 [PUT]
Traceback (most recent call last):
  File "/opt/homebrew/lib/python3.9/site-packages/flask/app.py", line 1950, in full_dispatch_request
    rv = self.dispatch_request()
  File "/opt/homebrew/lib/python3.9/site-packages/flask/app.py", line 1936, in dispatch_request
    return self.view_functions[rule.endpoint](**req.view_args)
  File "/opt/homebrew/lib/python3.9/site-packages/flask_restful/__init__.py", line 468, in wrapper
    resp = resource(*args, **kwargs)
  File "/opt/homebrew/lib/python3.9/site-packages/flask/views.py", line 89, in view
    return self.dispatch_request(*args, **kwargs)
  File "/opt/homebrew/lib/python3.9/site-packages/flask_restful/__init__.py", line 583, in dispatch_request
    resp = meth(*args, **kwargs)
  File "/Users/kiranattal/Desktop/MICROSERVICES/USER/user/resources/user.py", line 93, in put
    not_found(404)
  File "/Users/kiranattal/Desktop/MICROSERVICES/USER/user/resources/user.py", line 157, in not_found
    return make_response(jsonify({"error":"Not Found"+error}),404)
TypeError: can only concatenate str (not "int") to str
2022-02-07 21:44:46 INFO - 127.0.0.1 - - [07/Feb/2022 21:44:46] "[35m[1mPUT //user/User-f8f190a0-8683-11ec-8657-1e00310cd05 HTTP/1.1[0m" 500 -
2022-02-07 21:45:24 INFO -  * Running on http://127.0.0.1:5000/ (Press CTRL+C to quit)
2022-02-07 21:45:29 INFO - User-f8f190a0-8683-11ec-8657-1e00310cd05
2022-02-07 21:45:30 ERROR - Document doesnt existkiran_attal@scmhrd.edu
2022-02-07 21:45:30 INFO - 127.0.0.1 - - [07/Feb/2022 21:45:30] "[37mPUT //user/User-f8f190a0-8683-11ec-8657-1e00310cd05 HTTP/1.1[0m" 200 -
2022-02-07 22:01:25 INFO - User-f8f190a0-8683-11ec-8657-1e00310cd05
2022-02-07 22:01:26 ERROR - Document doesnt existkiran_attal@scmhrd.edu
2022-02-07 22:01:26 INFO - 127.0.0.1 - - [07/Feb/2022 22:01:26] "[37mPUT //user/User-f8f190a0-8683-11ec-8657-1e00310cd05 HTTP/1.1[0m" 200 -
2022-02-07 22:02:06 INFO -  * Running on http://127.0.0.1:5000/ (Press CTRL+C to quit)
2022-02-07 22:02:07 INFO - User-f8f190a0-8683-11ec-8657-1e00310cd05
2022-02-07 22:02:09 ERROR - Document doesnt existkiran_attal@scmhrd.edu
2022-02-07 22:02:09 INFO - 127.0.0.1 - - [07/Feb/2022 22:02:09] "[37mPUT //user/User-f8f190a0-8683-11ec-8657-1e00310cd05 HTTP/1.1[0m" 200 -
2022-02-07 22:03:07 INFO -  * Running on http://127.0.0.1:5000/ (Press CTRL+C to quit)
2022-02-07 22:03:08 INFO - User-f8f190a0-8683-11ec-8657-1e00310cd05
2022-02-07 22:03:10 ERROR - Document doesnt existkiran_attal@scmhrd.edu
2022-02-07 22:03:10 INFO - 127.0.0.1 - - [07/Feb/2022 22:03:10] "[33mPUT //user/User-f8f190a0-8683-11ec-8657-1e00310cd05 HTTP/1.1[0m" 404 -
2022-02-07 22:03:32 INFO -  * Running on http://127.0.0.1:5000/ (Press CTRL+C to quit)
2022-02-07 22:03:35 INFO - User-f8f190a0-8683-11ec-8657-1e00310cd05
2022-02-07 22:03:41 ERROR - Document doesnt existkiran_attal@scmhrd.edu
2022-02-07 22:03:41 INFO - 127.0.0.1 - - [07/Feb/2022 22:03:41] "[33mPUT //user/User-f8f190a0-8683-11ec-8657-1e00310cd05 HTTP/1.1[0m" 404 -
2022-02-09 00:51:54 INFO - Running user app
2022-02-09 00:51:54 INFO -  * Running on http://127.0.0.1:5000/ (Press CTRL+C to quit)
2022-02-09 00:52:18 INFO - User-f8f190a0-8683-11ec-8657-1e00310cd05
2022-02-09 00:52:19 ERROR - Document doesnt existkiran_attal@scmhrd.edu
2022-02-09 00:52:19 INFO - 127.0.0.1 - - [09/Feb/2022 00:52:19] "[33mPUT //user/User-f8f190a0-8683-11ec-8657-1e00310cd05 HTTP/1.1[0m" 404 -
2022-02-09 00:52:52 INFO - Ninad
2022-02-09 00:52:52 INFO - User-c187e1d0-8725-11ec-a8cf-1e00310cd079
2022-02-09 00:52:52 INFO - Ninad
2022-02-09 00:52:52 INFO - User-f8f190a0-8683-11ec-8657-1e00310cd078
2022-02-09 00:52:52 INFO - Ninad
2022-02-09 00:52:52 INFO - User-f91fe28e-8683-11ec-8657-1e00310cd078
2022-02-09 00:52:52 INFO - Ninad
2022-02-09 00:52:52 INFO - User-f950e58c-8683-11ec-8657-1e00310cd078
2022-02-09 00:52:52 INFO - Ninad
2022-02-09 00:52:52 INFO - User-f97cdb24-8683-11ec-8657-1e00310cd078
2022-02-09 00:52:52 INFO - 127.0.0.1 - - [09/Feb/2022 00:52:52] "GET /user/Ninad HTTP/1.1" 200 -
2022-02-18 11:31:38 INFO -  * Running on http://127.0.0.1:5000/ (Press CTRL+C to quit)
2022-02-18 11:33:31 ERROR - AuthMetadataPluginCallback "<google.auth.transport.grpc.AuthMetadataPlugin object at 0x1064a5a30>" raised exception!
Traceback (most recent call last):
  File "/opt/homebrew/lib/python3.9/site-packages/grpc/_plugin_wrapping.py", line 89, in __call__
    self._metadata_plugin(
  File "/opt/homebrew/lib/python3.9/site-packages/google/auth/transport/grpc.py", line 101, in __call__
    callback(self._get_authorization_headers(context), None)
  File "/opt/homebrew/lib/python3.9/site-packages/google/auth/transport/grpc.py", line 87, in _get_authorization_headers
    self._credentials.before_request(
  File "/opt/homebrew/lib/python3.9/site-packages/google/auth/credentials.py", line 133, in before_request
    self.refresh(request)
  File "/opt/homebrew/lib/python3.9/site-packages/google/oauth2/service_account.py", line 410, in refresh
    access_token, expiry, _ = _client.jwt_grant(
  File "/opt/homebrew/lib/python3.9/site-packages/google/oauth2/_client.py", line 193, in jwt_grant
    response_data = _token_endpoint_request(request, token_uri, body)
  File "/opt/homebrew/lib/python3.9/site-packages/google/oauth2/_client.py", line 165, in _token_endpoint_request
    _handle_error_response(response_data)
  File "/opt/homebrew/lib/python3.9/site-packages/google/oauth2/_client.py", line 60, in _handle_error_response
    raise exceptions.RefreshError(error_details, response_data)
google.auth.exceptions.RefreshError: ('invalid_grant: Invalid grant: account not found', {'error': 'invalid_grant', 'error_description': 'Invalid grant: account not found'})
2022-02-18 11:33:32 ERROR - AuthMetadataPluginCallback "<google.auth.transport.grpc.AuthMetadataPlugin object at 0x1064a5a30>" raised exception!
Traceback (most recent call last):
  File "/opt/homebrew/lib/python3.9/site-packages/grpc/_plugin_wrapping.py", line 89, in __call__
    self._metadata_plugin(
  File "/opt/homebrew/lib/python3.9/site-packages/google/auth/transport/grpc.py", line 101, in __call__
    callback(self._get_authorization_headers(context), None)
  File "/opt/homebrew/lib/python3.9/site-packages/google/auth/transport/grpc.py", line 87, in _get_authorization_headers
    self._credentials.before_request(
  File "/opt/homebrew/lib/python3.9/site-packages/google/auth/credentials.py", line 133, in before_request
    self.refresh(request)
  File "/opt/homebrew/lib/python3.9/site-packages/google/oauth2/service_account.py", line 410, in refresh
    access_token, expiry, _ = _client.jwt_grant(
  File "/opt/homebrew/lib/python3.9/site-packages/google/oauth2/_client.py", line 193, in jwt_grant
    response_data = _token_endpoint_request(request, token_uri, body)
  File "/opt/homebrew/lib/python3.9/site-packages/google/oauth2/_client.py", line 165, in _token_endpoint_request
    _handle_error_response(response_data)
  File "/opt/homebrew/lib/python3.9/site-packages/google/oauth2/_client.py", line 60, in _handle_error_response
    raise exceptions.RefreshError(error_details, response_data)
google.auth.exceptions.RefreshError: ('invalid_grant: Invalid grant: account not found', {'error': 'invalid_grant', 'error_description': 'Invalid grant: account not found'})
2022-02-18 11:33:32 ERROR - AuthMetadataPluginCallback "<google.auth.transport.grpc.AuthMetadataPlugin object at 0x1064a5a30>" raised exception!
Traceback (most recent call last):
  File "/opt/homebrew/lib/python3.9/site-packages/grpc/_plugin_wrapping.py", line 89, in __call__
    self._metadata_plugin(
  File "/opt/homebrew/lib/python3.9/site-packages/google/auth/transport/grpc.py", line 101, in __call__
    callback(self._get_authorization_headers(context), None)
  File "/opt/homebrew/lib/python3.9/site-packages/google/auth/transport/grpc.py", line 87, in _get_authorization_headers
    self._credentials.before_request(
  File "/opt/homebrew/lib/python3.9/site-packages/google/auth/credentials.py", line 133, in before_request
    self.refresh(request)
  File "/opt/homebrew/lib/python3.9/site-packages/google/oauth2/service_account.py", line 410, in refresh
    access_token, expiry, _ = _client.jwt_grant(
  File "/opt/homebrew/lib/python3.9/site-packages/google/oauth2/_client.py", line 193, in jwt_grant
    response_data = _token_endpoint_request(request, token_uri, body)
  File "/opt/homebrew/lib/python3.9/site-packages/google/oauth2/_client.py", line 165, in _token_endpoint_request
    _handle_error_response(response_data)
  File "/opt/homebrew/lib/python3.9/site-packages/google/oauth2/_client.py", line 60, in _handle_error_response
    raise exceptions.RefreshError(error_details, response_data)
google.auth.exceptions.RefreshError: ('invalid_grant: Invalid grant: account not found', {'error': 'invalid_grant', 'error_description': 'Invalid grant: account not found'})
2022-02-18 11:33:32 ERROR - AuthMetadataPluginCallback "<google.auth.transport.grpc.AuthMetadataPlugin object at 0x1064a5a30>" raised exception!
Traceback (most recent call last):
  File "/opt/homebrew/lib/python3.9/site-packages/grpc/_plugin_wrapping.py", line 89, in __call__
    self._metadata_plugin(
  File "/opt/homebrew/lib/python3.9/site-packages/google/auth/transport/grpc.py", line 101, in __call__
    callback(self._get_authorization_headers(context), None)
  File "/opt/homebrew/lib/python3.9/site-packages/google/auth/transport/grpc.py", line 87, in _get_authorization_headers
    self._credentials.before_request(
  File "/opt/homebrew/lib/python3.9/site-packages/google/auth/credentials.py", line 133, in before_request
    self.refresh(request)
  File "/opt/homebrew/lib/python3.9/site-packages/google/oauth2/service_account.py", line 410, in refresh
    access_token, expiry, _ = _client.jwt_grant(
  File "/opt/homebrew/lib/python3.9/site-packages/google/oauth2/_client.py", line 193, in jwt_grant
    response_data = _token_endpoint_request(request, token_uri, body)
  File "/opt/homebrew/lib/python3.9/site-packages/google/oauth2/_client.py", line 165, in _token_endpoint_request
    _handle_error_response(response_data)
  File "/opt/homebrew/lib/python3.9/site-packages/google/oauth2/_client.py", line 60, in _handle_error_response
    raise exceptions.RefreshError(error_details, response_data)
google.auth.exceptions.RefreshError: ('invalid_grant: Invalid grant: account not found', {'error': 'invalid_grant', 'error_description': 'Invalid grant: account not found'})
2022-02-18 11:33:33 ERROR - AuthMetadataPluginCallback "<google.auth.transport.grpc.AuthMetadataPlugin object at 0x1064a5a30>" raised exception!
Traceback (most recent call last):
  File "/opt/homebrew/lib/python3.9/site-packages/grpc/_plugin_wrapping.py", line 89, in __call__
    self._metadata_plugin(
  File "/opt/homebrew/lib/python3.9/site-packages/google/auth/transport/grpc.py", line 101, in __call__
    callback(self._get_authorization_headers(context), None)
  File "/opt/homebrew/lib/python3.9/site-packages/google/auth/transport/grpc.py", line 87, in _get_authorization_headers
    self._credentials.before_request(
  File "/opt/homebrew/lib/python3.9/site-packages/google/auth/credentials.py", line 133, in before_request
    self.refresh(request)
  File "/opt/homebrew/lib/python3.9/site-packages/google/oauth2/service_account.py", line 410, in refresh
    access_token, expiry, _ = _client.jwt_grant(
  File "/opt/homebrew/lib/python3.9/site-packages/google/oauth2/_client.py", line 193, in jwt_grant
    response_data = _token_endpoint_request(request, token_uri, body)
  File "/opt/homebrew/lib/python3.9/site-packages/google/oauth2/_client.py", line 165, in _token_endpoint_request
    _handle_error_response(response_data)
  File "/opt/homebrew/lib/python3.9/site-packages/google/oauth2/_client.py", line 60, in _handle_error_response
    raise exceptions.RefreshError(error_details, response_data)
google.auth.exceptions.RefreshError: ('invalid_grant: Invalid grant: account not found', {'error': 'invalid_grant', 'error_description': 'Invalid grant: account not found'})
2022-02-18 11:33:34 ERROR - AuthMetadataPluginCallback "<google.auth.transport.grpc.AuthMetadataPlugin object at 0x1064a5a30>" raised exception!
Traceback (most recent call last):
  File "/opt/homebrew/lib/python3.9/site-packages/grpc/_plugin_wrapping.py", line 89, in __call__
    self._metadata_plugin(
  File "/opt/homebrew/lib/python3.9/site-packages/google/auth/transport/grpc.py", line 101, in __call__
    callback(self._get_authorization_headers(context), None)
  File "/opt/homebrew/lib/python3.9/site-packages/google/auth/transport/grpc.py", line 87, in _get_authorization_headers
    self._credentials.before_request(
  File "/opt/homebrew/lib/python3.9/site-packages/google/auth/credentials.py", line 133, in before_request
    self.refresh(request)
  File "/opt/homebrew/lib/python3.9/site-packages/google/oauth2/service_account.py", line 410, in refresh
    access_token, expiry, _ = _client.jwt_grant(
  File "/opt/homebrew/lib/python3.9/site-packages/google/oauth2/_client.py", line 193, in jwt_grant
    response_data = _token_endpoint_request(request, token_uri, body)
  File "/opt/homebrew/lib/python3.9/site-packages/google/oauth2/_client.py", line 165, in _token_endpoint_request
    _handle_error_response(response_data)
  File "/opt/homebrew/lib/python3.9/site-packages/google/oauth2/_client.py", line 60, in _handle_error_response
    raise exceptions.RefreshError(error_details, response_data)
google.auth.exceptions.RefreshError: ('invalid_grant: Invalid grant: account not found', {'error': 'invalid_grant', 'error_description': 'Invalid grant: account not found'})
2022-02-18 11:33:35 ERROR - AuthMetadataPluginCallback "<google.auth.transport.grpc.AuthMetadataPlugin object at 0x1064a5a30>" raised exception!
Traceback (most recent call last):
  File "/opt/homebrew/lib/python3.9/site-packages/grpc/_plugin_wrapping.py", line 89, in __call__
    self._metadata_plugin(
  File "/opt/homebrew/lib/python3.9/site-packages/google/auth/transport/grpc.py", line 101, in __call__
    callback(self._get_authorization_headers(context), None)
  File "/opt/homebrew/lib/python3.9/site-packages/google/auth/transport/grpc.py", line 87, in _get_authorization_headers
    self._credentials.before_request(
  File "/opt/homebrew/lib/python3.9/site-packages/google/auth/credentials.py", line 133, in before_request
    self.refresh(request)
  File "/opt/homebrew/lib/python3.9/site-packages/google/oauth2/service_account.py", line 410, in refresh
    access_token, expiry, _ = _client.jwt_grant(
  File "/opt/homebrew/lib/python3.9/site-packages/google/oauth2/_client.py", line 193, in jwt_grant
    response_data = _token_endpoint_request(request, token_uri, body)
  File "/opt/homebrew/lib/python3.9/site-packages/google/oauth2/_client.py", line 165, in _token_endpoint_request
    _handle_error_response(response_data)
  File "/opt/homebrew/lib/python3.9/site-packages/google/oauth2/_client.py", line 60, in _handle_error_response
    raise exceptions.RefreshError(error_details, response_data)
google.auth.exceptions.RefreshError: ('invalid_grant: Invalid grant: account not found', {'error': 'invalid_grant', 'error_description': 'Invalid grant: account not found'})
2022-02-18 11:33:35 ERROR - AuthMetadataPluginCallback "<google.auth.transport.grpc.AuthMetadataPlugin object at 0x1064a5a30>" raised exception!
Traceback (most recent call last):
  File "/opt/homebrew/lib/python3.9/site-packages/grpc/_plugin_wrapping.py", line 89, in __call__
    self._metadata_plugin(
  File "/opt/homebrew/lib/python3.9/site-packages/google/auth/transport/grpc.py", line 101, in __call__
    callback(self._get_authorization_headers(context), None)
  File "/opt/homebrew/lib/python3.9/site-packages/google/auth/transport/grpc.py", line 87, in _get_authorization_headers
    self._credentials.before_request(
  File "/opt/homebrew/lib/python3.9/site-packages/google/auth/credentials.py", line 133, in before_request
    self.refresh(request)
  File "/opt/homebrew/lib/python3.9/site-packages/google/oauth2/service_account.py", line 410, in refresh
    access_token, expiry, _ = _client.jwt_grant(
  File "/opt/homebrew/lib/python3.9/site-packages/google/oauth2/_client.py", line 193, in jwt_grant
    response_data = _token_endpoint_request(request, token_uri, body)
  File "/opt/homebrew/lib/python3.9/site-packages/google/oauth2/_client.py", line 165, in _token_endpoint_request
    _handle_error_response(response_data)
  File "/opt/homebrew/lib/python3.9/site-packages/google/oauth2/_client.py", line 60, in _handle_error_response
    raise exceptions.RefreshError(error_details, response_data)
google.auth.exceptions.RefreshError: ('invalid_grant: Invalid grant: account not found', {'error': 'invalid_grant', 'error_description': 'Invalid grant: account not found'})
2022-02-18 11:33:36 ERROR - AuthMetadataPluginCallback "<google.auth.transport.grpc.AuthMetadataPlugin object at 0x1064a5a30>" raised exception!
Traceback (most recent call last):
  File "/opt/homebrew/lib/python3.9/site-packages/grpc/_plugin_wrapping.py", line 89, in __call__
    self._metadata_plugin(
  File "/opt/homebrew/lib/python3.9/site-packages/google/auth/transport/grpc.py", line 101, in __call__
    callback(self._get_authorization_headers(context), None)
  File "/opt/homebrew/lib/python3.9/site-packages/google/auth/transport/grpc.py", line 87, in _get_authorization_headers
    self._credentials.before_request(
  File "/opt/homebrew/lib/python3.9/site-packages/google/auth/credentials.py", line 133, in before_request
    self.refresh(request)
  File "/opt/homebrew/lib/python3.9/site-packages/google/oauth2/service_account.py", line 410, in refresh
    access_token, expiry, _ = _client.jwt_grant(
  File "/opt/homebrew/lib/python3.9/site-packages/google/oauth2/_client.py", line 193, in jwt_grant
    response_data = _token_endpoint_request(request, token_uri, body)
  File "/opt/homebrew/lib/python3.9/site-packages/google/oauth2/_client.py", line 165, in _token_endpoint_request
    _handle_error_response(response_data)
  File "/opt/homebrew/lib/python3.9/site-packages/google/oauth2/_client.py", line 60, in _handle_error_response
    raise exceptions.RefreshError(error_details, response_data)
google.auth.exceptions.RefreshError: ('invalid_grant: Invalid grant: account not found', {'error': 'invalid_grant', 'error_description': 'Invalid grant: account not found'})
2022-02-18 11:33:37 ERROR - AuthMetadataPluginCallback "<google.auth.transport.grpc.AuthMetadataPlugin object at 0x1064a5a30>" raised exception!
Traceback (most recent call last):
  File "/opt/homebrew/lib/python3.9/site-packages/grpc/_plugin_wrapping.py", line 89, in __call__
    self._metadata_plugin(
  File "/opt/homebrew/lib/python3.9/site-packages/google/auth/transport/grpc.py", line 101, in __call__
    callback(self._get_authorization_headers(context), None)
  File "/opt/homebrew/lib/python3.9/site-packages/google/auth/transport/grpc.py", line 87, in _get_authorization_headers
    self._credentials.before_request(
  File "/opt/homebrew/lib/python3.9/site-packages/google/auth/credentials.py", line 133, in before_request
    self.refresh(request)
  File "/opt/homebrew/lib/python3.9/site-packages/google/oauth2/service_account.py", line 410, in refresh
    access_token, expiry, _ = _client.jwt_grant(
  File "/opt/homebrew/lib/python3.9/site-packages/google/oauth2/_client.py", line 193, in jwt_grant
    response_data = _token_endpoint_request(request, token_uri, body)
  File "/opt/homebrew/lib/python3.9/site-packages/google/oauth2/_client.py", line 165, in _token_endpoint_request
    _handle_error_response(response_data)
  File "/opt/homebrew/lib/python3.9/site-packages/google/oauth2/_client.py", line 60, in _handle_error_response
    raise exceptions.RefreshError(error_details, response_data)
google.auth.exceptions.RefreshError: ('invalid_grant: Invalid grant: account not found', {'error': 'invalid_grant', 'error_description': 'Invalid grant: account not found'})
2022-02-18 11:33:38 ERROR - AuthMetadataPluginCallback "<google.auth.transport.grpc.AuthMetadataPlugin object at 0x1064a5a30>" raised exception!
Traceback (most recent call last):
  File "/opt/homebrew/lib/python3.9/site-packages/grpc/_plugin_wrapping.py", line 89, in __call__
    self._metadata_plugin(
  File "/opt/homebrew/lib/python3.9/site-packages/google/auth/transport/grpc.py", line 101, in __call__
    callback(self._get_authorization_headers(context), None)
  File "/opt/homebrew/lib/python3.9/site-packages/google/auth/transport/grpc.py", line 87, in _get_authorization_headers
    self._credentials.before_request(
  File "/opt/homebrew/lib/python3.9/site-packages/google/auth/credentials.py", line 133, in before_request
    self.refresh(request)
  File "/opt/homebrew/lib/python3.9/site-packages/google/oauth2/service_account.py", line 410, in refresh
    access_token, expiry, _ = _client.jwt_grant(
  File "/opt/homebrew/lib/python3.9/site-packages/google/oauth2/_client.py", line 193, in jwt_grant
    response_data = _token_endpoint_request(request, token_uri, body)
  File "/opt/homebrew/lib/python3.9/site-packages/google/oauth2/_client.py", line 165, in _token_endpoint_request
    _handle_error_response(response_data)
  File "/opt/homebrew/lib/python3.9/site-packages/google/oauth2/_client.py", line 60, in _handle_error_response
    raise exceptions.RefreshError(error_details, response_data)
google.auth.exceptions.RefreshError: ('invalid_grant: Invalid grant: account not found', {'error': 'invalid_grant', 'error_description': 'Invalid grant: account not found'})
2022-02-18 11:33:39 ERROR - AuthMetadataPluginCallback "<google.auth.transport.grpc.AuthMetadataPlugin object at 0x1064a5a30>" raised exception!
Traceback (most recent call last):
  File "/opt/homebrew/lib/python3.9/site-packages/grpc/_plugin_wrapping.py", line 89, in __call__
    self._metadata_plugin(
  File "/opt/homebrew/lib/python3.9/site-packages/google/auth/transport/grpc.py", line 101, in __call__
    callback(self._get_authorization_headers(context), None)
  File "/opt/homebrew/lib/python3.9/site-packages/google/auth/transport/grpc.py", line 87, in _get_authorization_headers
    self._credentials.before_request(
  File "/opt/homebrew/lib/python3.9/site-packages/google/auth/credentials.py", line 133, in before_request
    self.refresh(request)
  File "/opt/homebrew/lib/python3.9/site-packages/google/oauth2/service_account.py", line 410, in refresh
    access_token, expiry, _ = _client.jwt_grant(
  File "/opt/homebrew/lib/python3.9/site-packages/google/oauth2/_client.py", line 193, in jwt_grant
    response_data = _token_endpoint_request(request, token_uri, body)
  File "/opt/homebrew/lib/python3.9/site-packages/google/oauth2/_client.py", line 165, in _token_endpoint_request
    _handle_error_response(response_data)
  File "/opt/homebrew/lib/python3.9/site-packages/google/oauth2/_client.py", line 60, in _handle_error_response
    raise exceptions.RefreshError(error_details, response_data)
google.auth.exceptions.RefreshError: ('invalid_grant: Invalid grant: account not found', {'error': 'invalid_grant', 'error_description': 'Invalid grant: account not found'})
2022-02-18 11:33:43 ERROR - AuthMetadataPluginCallback "<google.auth.transport.grpc.AuthMetadataPlugin object at 0x1064a5a30>" raised exception!
Traceback (most recent call last):
  File "/opt/homebrew/lib/python3.9/site-packages/grpc/_plugin_wrapping.py", line 89, in __call__
    self._metadata_plugin(
  File "/opt/homebrew/lib/python3.9/site-packages/google/auth/transport/grpc.py", line 101, in __call__
    callback(self._get_authorization_headers(context), None)
  File "/opt/homebrew/lib/python3.9/site-packages/google/auth/transport/grpc.py", line 87, in _get_authorization_headers
    self._credentials.before_request(
  File "/opt/homebrew/lib/python3.9/site-packages/google/auth/credentials.py", line 133, in before_request
    self.refresh(request)
  File "/opt/homebrew/lib/python3.9/site-packages/google/oauth2/service_account.py", line 410, in refresh
    access_token, expiry, _ = _client.jwt_grant(
  File "/opt/homebrew/lib/python3.9/site-packages/google/oauth2/_client.py", line 193, in jwt_grant
    response_data = _token_endpoint_request(request, token_uri, body)
  File "/opt/homebrew/lib/python3.9/site-packages/google/oauth2/_client.py", line 165, in _token_endpoint_request
    _handle_error_response(response_data)
  File "/opt/homebrew/lib/python3.9/site-packages/google/oauth2/_client.py", line 60, in _handle_error_response
    raise exceptions.RefreshError(error_details, response_data)
google.auth.exceptions.RefreshError: ('invalid_grant: Invalid grant: account not found', {'error': 'invalid_grant', 'error_description': 'Invalid grant: account not found'})
2022-02-18 11:33:46 ERROR - AuthMetadataPluginCallback "<google.auth.transport.grpc.AuthMetadataPlugin object at 0x1064a5a30>" raised exception!
Traceback (most recent call last):
  File "/opt/homebrew/lib/python3.9/site-packages/grpc/_plugin_wrapping.py", line 89, in __call__
    self._metadata_plugin(
  File "/opt/homebrew/lib/python3.9/site-packages/google/auth/transport/grpc.py", line 101, in __call__
    callback(self._get_authorization_headers(context), None)
  File "/opt/homebrew/lib/python3.9/site-packages/google/auth/transport/grpc.py", line 87, in _get_authorization_headers
    self._credentials.before_request(
  File "/opt/homebrew/lib/python3.9/site-packages/google/auth/credentials.py", line 133, in before_request
    self.refresh(request)
  File "/opt/homebrew/lib/python3.9/site-packages/google/oauth2/service_account.py", line 410, in refresh
    access_token, expiry, _ = _client.jwt_grant(
  File "/opt/homebrew/lib/python3.9/site-packages/google/oauth2/_client.py", line 193, in jwt_grant
    response_data = _token_endpoint_request(request, token_uri, body)
  File "/opt/homebrew/lib/python3.9/site-packages/google/oauth2/_client.py", line 165, in _token_endpoint_request
    _handle_error_response(response_data)
  File "/opt/homebrew/lib/python3.9/site-packages/google/oauth2/_client.py", line 60, in _handle_error_response
    raise exceptions.RefreshError(error_details, response_data)
google.auth.exceptions.RefreshError: ('invalid_grant: Invalid grant: account not found', {'error': 'invalid_grant', 'error_description': 'Invalid grant: account not found'})
2022-02-18 11:33:48 ERROR - AuthMetadataPluginCallback "<google.auth.transport.grpc.AuthMetadataPlugin object at 0x1064a5a30>" raised exception!
Traceback (most recent call last):
  File "/opt/homebrew/lib/python3.9/site-packages/grpc/_plugin_wrapping.py", line 89, in __call__
    self._metadata_plugin(
  File "/opt/homebrew/lib/python3.9/site-packages/google/auth/transport/grpc.py", line 101, in __call__
    callback(self._get_authorization_headers(context), None)
  File "/opt/homebrew/lib/python3.9/site-packages/google/auth/transport/grpc.py", line 87, in _get_authorization_headers
    self._credentials.before_request(
  File "/opt/homebrew/lib/python3.9/site-packages/google/auth/credentials.py", line 133, in before_request
    self.refresh(request)
  File "/opt/homebrew/lib/python3.9/site-packages/google/oauth2/service_account.py", line 410, in refresh
    access_token, expiry, _ = _client.jwt_grant(
  File "/opt/homebrew/lib/python3.9/site-packages/google/oauth2/_client.py", line 193, in jwt_grant
    response_data = _token_endpoint_request(request, token_uri, body)
  File "/opt/homebrew/lib/python3.9/site-packages/google/oauth2/_client.py", line 165, in _token_endpoint_request
    _handle_error_response(response_data)
  File "/opt/homebrew/lib/python3.9/site-packages/google/oauth2/_client.py", line 60, in _handle_error_response
    raise exceptions.RefreshError(error_details, response_data)
google.auth.exceptions.RefreshError: ('invalid_grant: Invalid grant: account not found', {'error': 'invalid_grant', 'error_description': 'Invalid grant: account not found'})
2022-02-18 11:33:48 ERROR - AuthMetadataPluginCallback "<google.auth.transport.grpc.AuthMetadataPlugin object at 0x1064a5a30>" raised exception!
Traceback (most recent call last):
  File "/opt/homebrew/lib/python3.9/site-packages/grpc/_plugin_wrapping.py", line 89, in __call__
    self._metadata_plugin(
  File "/opt/homebrew/lib/python3.9/site-packages/google/auth/transport/grpc.py", line 101, in __call__
    callback(self._get_authorization_headers(context), None)
  File "/opt/homebrew/lib/python3.9/site-packages/google/auth/transport/grpc.py", line 87, in _get_authorization_headers
    self._credentials.before_request(
  File "/opt/homebrew/lib/python3.9/site-packages/google/auth/credentials.py", line 133, in before_request
    self.refresh(request)
  File "/opt/homebrew/lib/python3.9/site-packages/google/oauth2/service_account.py", line 410, in refresh
    access_token, expiry, _ = _client.jwt_grant(
  File "/opt/homebrew/lib/python3.9/site-packages/google/oauth2/_client.py", line 193, in jwt_grant
    response_data = _token_endpoint_request(request, token_uri, body)
  File "/opt/homebrew/lib/python3.9/site-packages/google/oauth2/_client.py", line 165, in _token_endpoint_request
    _handle_error_response(response_data)
  File "/opt/homebrew/lib/python3.9/site-packages/google/oauth2/_client.py", line 60, in _handle_error_response
    raise exceptions.RefreshError(error_details, response_data)
google.auth.exceptions.RefreshError: ('invalid_grant: Invalid grant: account not found', {'error': 'invalid_grant', 'error_description': 'Invalid grant: account not found'})
2022-02-18 11:33:54 ERROR - AuthMetadataPluginCallback "<google.auth.transport.grpc.AuthMetadataPlugin object at 0x1064a5a30>" raised exception!
Traceback (most recent call last):
  File "/opt/homebrew/lib/python3.9/site-packages/grpc/_plugin_wrapping.py", line 89, in __call__
    self._metadata_plugin(
  File "/opt/homebrew/lib/python3.9/site-packages/google/auth/transport/grpc.py", line 101, in __call__
    callback(self._get_authorization_headers(context), None)
  File "/opt/homebrew/lib/python3.9/site-packages/google/auth/transport/grpc.py", line 87, in _get_authorization_headers
    self._credentials.before_request(
  File "/opt/homebrew/lib/python3.9/site-packages/google/auth/credentials.py", line 133, in before_request
    self.refresh(request)
  File "/opt/homebrew/lib/python3.9/site-packages/google/oauth2/service_account.py", line 410, in refresh
    access_token, expiry, _ = _client.jwt_grant(
  File "/opt/homebrew/lib/python3.9/site-packages/google/oauth2/_client.py", line 193, in jwt_grant
    response_data = _token_endpoint_request(request, token_uri, body)
  File "/opt/homebrew/lib/python3.9/site-packages/google/oauth2/_client.py", line 165, in _token_endpoint_request
    _handle_error_response(response_data)
  File "/opt/homebrew/lib/python3.9/site-packages/google/oauth2/_client.py", line 60, in _handle_error_response
    raise exceptions.RefreshError(error_details, response_data)
google.auth.exceptions.RefreshError: ('invalid_grant: Invalid grant: account not found', {'error': 'invalid_grant', 'error_description': 'Invalid grant: account not found'})
2022-02-18 11:34:03 ERROR - AuthMetadataPluginCallback "<google.auth.transport.grpc.AuthMetadataPlugin object at 0x1064a5a30>" raised exception!
Traceback (most recent call last):
  File "/opt/homebrew/lib/python3.9/site-packages/grpc/_plugin_wrapping.py", line 89, in __call__
    self._metadata_plugin(
  File "/opt/homebrew/lib/python3.9/site-packages/google/auth/transport/grpc.py", line 101, in __call__
    callback(self._get_authorization_headers(context), None)
  File "/opt/homebrew/lib/python3.9/site-packages/google/auth/transport/grpc.py", line 87, in _get_authorization_headers
    self._credentials.before_request(
  File "/opt/homebrew/lib/python3.9/site-packages/google/auth/credentials.py", line 133, in before_request
    self.refresh(request)
  File "/opt/homebrew/lib/python3.9/site-packages/google/oauth2/service_account.py", line 410, in refresh
    access_token, expiry, _ = _client.jwt_grant(
  File "/opt/homebrew/lib/python3.9/site-packages/google/oauth2/_client.py", line 193, in jwt_grant
    response_data = _token_endpoint_request(request, token_uri, body)
  File "/opt/homebrew/lib/python3.9/site-packages/google/oauth2/_client.py", line 165, in _token_endpoint_request
    _handle_error_response(response_data)
  File "/opt/homebrew/lib/python3.9/site-packages/google/oauth2/_client.py", line 60, in _handle_error_response
    raise exceptions.RefreshError(error_details, response_data)
google.auth.exceptions.RefreshError: ('invalid_grant: Invalid grant: account not found', {'error': 'invalid_grant', 'error_description': 'Invalid grant: account not found'})
2022-02-18 11:34:11 ERROR - AuthMetadataPluginCallback "<google.auth.transport.grpc.AuthMetadataPlugin object at 0x1064a5a30>" raised exception!
Traceback (most recent call last):
  File "/opt/homebrew/lib/python3.9/site-packages/grpc/_plugin_wrapping.py", line 89, in __call__
    self._metadata_plugin(
  File "/opt/homebrew/lib/python3.9/site-packages/google/auth/transport/grpc.py", line 101, in __call__
    callback(self._get_authorization_headers(context), None)
  File "/opt/homebrew/lib/python3.9/site-packages/google/auth/transport/grpc.py", line 87, in _get_authorization_headers
    self._credentials.before_request(
  File "/opt/homebrew/lib/python3.9/site-packages/google/auth/credentials.py", line 133, in before_request
    self.refresh(request)
  File "/opt/homebrew/lib/python3.9/site-packages/google/oauth2/service_account.py", line 410, in refresh
    access_token, expiry, _ = _client.jwt_grant(
  File "/opt/homebrew/lib/python3.9/site-packages/google/oauth2/_client.py", line 193, in jwt_grant
    response_data = _token_endpoint_request(request, token_uri, body)
  File "/opt/homebrew/lib/python3.9/site-packages/google/oauth2/_client.py", line 165, in _token_endpoint_request
    _handle_error_response(response_data)
  File "/opt/homebrew/lib/python3.9/site-packages/google/oauth2/_client.py", line 60, in _handle_error_response
    raise exceptions.RefreshError(error_details, response_data)
google.auth.exceptions.RefreshError: ('invalid_grant: Invalid grant: account not found', {'error': 'invalid_grant', 'error_description': 'Invalid grant: account not found'})
2022-02-18 11:34:26 ERROR - AuthMetadataPluginCallback "<google.auth.transport.grpc.AuthMetadataPlugin object at 0x1064a5a30>" raised exception!
Traceback (most recent call last):
  File "/opt/homebrew/lib/python3.9/site-packages/grpc/_plugin_wrapping.py", line 89, in __call__
    self._metadata_plugin(
  File "/opt/homebrew/lib/python3.9/site-packages/google/auth/transport/grpc.py", line 101, in __call__
    callback(self._get_authorization_headers(context), None)
  File "/opt/homebrew/lib/python3.9/site-packages/google/auth/transport/grpc.py", line 87, in _get_authorization_headers
    self._credentials.before_request(
  File "/opt/homebrew/lib/python3.9/site-packages/google/auth/credentials.py", line 133, in before_request
    self.refresh(request)
  File "/opt/homebrew/lib/python3.9/site-packages/google/oauth2/service_account.py", line 410, in refresh
    access_token, expiry, _ = _client.jwt_grant(
  File "/opt/homebrew/lib/python3.9/site-packages/google/oauth2/_client.py", line 193, in jwt_grant
    response_data = _token_endpoint_request(request, token_uri, body)
  File "/opt/homebrew/lib/python3.9/site-packages/google/oauth2/_client.py", line 165, in _token_endpoint_request
    _handle_error_response(response_data)
  File "/opt/homebrew/lib/python3.9/site-packages/google/oauth2/_client.py", line 60, in _handle_error_response
    raise exceptions.RefreshError(error_details, response_data)
google.auth.exceptions.RefreshError: ('invalid_grant: Invalid grant: account not found', {'error': 'invalid_grant', 'error_description': 'Invalid grant: account not found'})
2022-02-18 11:34:51 ERROR - AuthMetadataPluginCallback "<google.auth.transport.grpc.AuthMetadataPlugin object at 0x1064a5a30>" raised exception!
Traceback (most recent call last):
  File "/opt/homebrew/lib/python3.9/site-packages/grpc/_plugin_wrapping.py", line 89, in __call__
    self._metadata_plugin(
  File "/opt/homebrew/lib/python3.9/site-packages/google/auth/transport/grpc.py", line 101, in __call__
    callback(self._get_authorization_headers(context), None)
  File "/opt/homebrew/lib/python3.9/site-packages/google/auth/transport/grpc.py", line 87, in _get_authorization_headers
    self._credentials.before_request(
  File "/opt/homebrew/lib/python3.9/site-packages/google/auth/credentials.py", line 133, in before_request
    self.refresh(request)
  File "/opt/homebrew/lib/python3.9/site-packages/google/oauth2/service_account.py", line 410, in refresh
    access_token, expiry, _ = _client.jwt_grant(
  File "/opt/homebrew/lib/python3.9/site-packages/google/oauth2/_client.py", line 193, in jwt_grant
    response_data = _token_endpoint_request(request, token_uri, body)
  File "/opt/homebrew/lib/python3.9/site-packages/google/oauth2/_client.py", line 165, in _token_endpoint_request
    _handle_error_response(response_data)
  File "/opt/homebrew/lib/python3.9/site-packages/google/oauth2/_client.py", line 60, in _handle_error_response
    raise exceptions.RefreshError(error_details, response_data)
google.auth.exceptions.RefreshError: ('invalid_grant: Invalid grant: account not found', {'error': 'invalid_grant', 'error_description': 'Invalid grant: account not found'})
2022-02-18 11:35:18 ERROR - AuthMetadataPluginCallback "<google.auth.transport.grpc.AuthMetadataPlugin object at 0x1064a5a30>" raised exception!
Traceback (most recent call last):
  File "/opt/homebrew/lib/python3.9/site-packages/grpc/_plugin_wrapping.py", line 89, in __call__
    self._metadata_plugin(
  File "/opt/homebrew/lib/python3.9/site-packages/google/auth/transport/grpc.py", line 101, in __call__
    callback(self._get_authorization_headers(context), None)
  File "/opt/homebrew/lib/python3.9/site-packages/google/auth/transport/grpc.py", line 87, in _get_authorization_headers
    self._credentials.before_request(
  File "/opt/homebrew/lib/python3.9/site-packages/google/auth/credentials.py", line 133, in before_request
    self.refresh(request)
  File "/opt/homebrew/lib/python3.9/site-packages/google/oauth2/service_account.py", line 410, in refresh
    access_token, expiry, _ = _client.jwt_grant(
  File "/opt/homebrew/lib/python3.9/site-packages/google/oauth2/_client.py", line 193, in jwt_grant
    response_data = _token_endpoint_request(request, token_uri, body)
  File "/opt/homebrew/lib/python3.9/site-packages/google/oauth2/_client.py", line 165, in _token_endpoint_request
    _handle_error_response(response_data)
  File "/opt/homebrew/lib/python3.9/site-packages/google/oauth2/_client.py", line 60, in _handle_error_response
    raise exceptions.RefreshError(error_details, response_data)
google.auth.exceptions.RefreshError: ('invalid_grant: Invalid grant: account not found', {'error': 'invalid_grant', 'error_description': 'Invalid grant: account not found'})
2022-03-14 18:15:54 INFO -  * Running on http://127.0.0.1:5000/ (Press CTRL+C to quit)
2022-03-14 18:16:12 INFO - {'date_of_birth': '250788', 'first_name': 'Kiran', 'number_of_friends': 0, 'email': 'attal.kiran@gmail.com', 'last_name': 'Attal', 'is_active': True, 'user_id': 'User-c187e1d0-8725-11ec-a8cf-1e00310cd079'}
2022-03-14 18:16:12 INFO - 127.0.0.1 - - [14/Mar/2022 18:16:12] "[31m[1mPOST /user HTTP/1.1[0m" 400 -
2022-03-14 18:16:13 INFO - {'first_name': 'Kiran', 'email': 'attal.kiran@gmail.com', 'date_of_birth': '250788', 'last_name': 'Attal', 'number_of_friends': 0, 'is_active': True, 'user_id': 'User-c187e1d0-8725-11ec-a8cf-1e00310cd079'}
2022-03-14 18:16:13 INFO - 127.0.0.1 - - [14/Mar/2022 18:16:13] "[31m[1mPOST /user HTTP/1.1[0m" 400 -
2022-03-14 18:16:13 INFO - {'email': 'attal.kiran@gmail.com', 'date_of_birth': '250788', 'last_name': 'Attal', 'user_id': 'User-c187e1d0-8725-11ec-a8cf-1e00310cd079', 'is_active': True, 'first_name': 'Kiran', 'number_of_friends': 0}
2022-03-14 18:16:13 INFO - 127.0.0.1 - - [14/Mar/2022 18:16:13] "[31m[1mPOST /user HTTP/1.1[0m" 400 -
2022-03-14 18:16:13 INFO - {'last_name': 'Attal', 'email': 'attal.kiran@gmail.com', 'user_id': 'User-c187e1d0-8725-11ec-a8cf-1e00310cd079', 'first_name': 'Kiran', 'is_active': True, 'date_of_birth': '250788', 'number_of_friends': 0}
2022-03-14 18:16:13 INFO - 127.0.0.1 - - [14/Mar/2022 18:16:13] "[31m[1mPOST /user HTTP/1.1[0m" 400 -
2022-03-14 18:18:02 INFO - User-c187e1d0-8725-11ec-a8cf-1e00310cd079
2022-03-14 18:18:02 INFO - User-c187e1d0-8725-11ec-a8cf-1e00310cd079
2022-03-14 18:18:03 INFO - 127.0.0.1 - - [14/Mar/2022 18:18:03] "[37mGET /user/User-c187e1d0-8725-11ec-a8cf-1e00310cd079 HTTP/1.1[0m" 200 -
